Traceback (most recent call last):
  File "P10.py", line 21, in test_traceback
    raise Exception('This is the error message')
Exception: This is the error message
